<?xml version="1.0" ?>

<!-- URDF Created from information in the following Paper:

Nguyen, Phung Khac, and Peter C. Hughes. "Teleoperation: from the space shuttle to the space station." Progress in astronautics and aeronautics 161 (1994): 353-353.

 -->

<robot name="SRMS_Canadarm">

  <!-- Colors -->
  <material name="Grey">
    <color rgba="0.2 0.2 0.2 1.0"/>
  </material>
  <material name="Orange">
    <color rgba="1.0 0.423529411765 0.0392156862745 1.0"/>
  </material>
  <material name="Blue">
  <color rgba="0.5 0.7 1.0 1.0"/>      
  </material>
  <material name="Red">
    <color rgba="1 0 0 1.0"/>      
  </material>

  <!-- SRMS_Canadarm Dummy Base Body-->
  <link name="Base_SRMS">
    <inertial>
      <origin rpy="0 0 0" xyz="0 0 0"/>
      <mass value="1"/>
      <inertia ixx="1" ixy="0" ixz="0" iyy="1" iyz="0" izz="1"/>
    </inertial>
    <visual>
      <origin rpy="0 0 0" xyz="0 0 0"/>
      <geometry>
        <box size="1.5 2 1" />
      </geometry>
      <material name="Grey"/>
    </visual>
  </link>

  <!-- Dummy Joint Joining Base to Body B1 -->
  <joint name="dummyBaseJoint" type="fixed">
    <parent link="Base_SRMS"/>
    <child link="B1"/>
    <!-- Rotate Frame to Match the frames on Fig. 13 in Paper -->
    <origin rpy="3.1416 0 0" xyz="0 0 0.5"/>
  </joint>


  <!--Manipulator-->
  <!-- Link 1 -->
  <link name="B1">

    <inertial>
      <origin rpy="0 0 0" xyz="0 0 -0.2856"/>
      <mass value="63.24"/>
      <inertia ixx="3.664" ixy="0.0044" ixz="0.0047" iyy="3.803" iyz="0.506" izz="0.686"/>
    </inertial>

    <visual>
      <origin rpy="0 0 0" xyz="0 0 -0.2586"/>
      <geometry>
        <cylinder radius="0.06" length="0.5172"/>
      </geometry>
      <material name="Blue"/>
    </visual>

  </link>


  <!-- Joint 1: Shoulder Yaw Joint -->
  <joint name="Shoulder_Yaw" type="revolute">
    <parent link="B1"/>
    <child link="B2"/>
    <origin rpy="0 0 0" xyz="0 0 -0.5172"/>
    <axis xyz="0 0 1"/>
    <limit lower="-3.0962" upper="3.0962" effort="1570" velocity="0.03997"/>
  </joint>

  <!-- Link 2 -->
  <link name="B2">

    <inertial>
      <origin rpy="0 0 0" xyz="0 0 -0.1524"/>
      <mass value="32.12"/>
      <inertia ixx="1.115" ixy="-0.019" ixz="-0.08" iyy="1.417" iyz="-0.037" izz="0.595"/>
    </inertial>

    <visual>
      <origin rpy="0 0 0" xyz="0 0 -0.1524"/>
      <geometry>
        <cylinder radius="0.06" length="0.3048"/>
      </geometry>
      <material name="Blue"/>
    </visual>

    <visual>
      <origin rpy="0 0 0" xyz="0 0 0.02"/>
      <geometry>
        <cylinder radius="0.1" length="0.04"/>
      </geometry>
      <material name="Red"/>
    </visual>

  </link>


  <!-- Joint 2: Shoulder Pitch Joint -->
  <joint name="Shoulder_Pitch" type="revolute">
    <parent link="B2"/>
    <child link="B3"/>
    <origin rpy="0 0 0" xyz="0 0 -0.3048"/>
    <axis xyz="0 1 0"/>
    <limit lower="0" upper="2.485" effort="1570" velocity="0.03997"/>
  </joint>


  <!-- Link 3 -->
  <link name="B3">

    <inertial>
      <origin rpy="0 0 0" xyz="3.1883 0 0.0282"/>
      <mass value="139.35"/>
      <inertia ixx="3.225" ixy="-1.928" ixz="9.185" iyy="998.63" iyz="-0.0302" izz="997.18"/>
    </inertial>

    <visual>
      <origin rpy="1.5708 0 1.5708" xyz="3.175 0 0"/>
      <geometry>
        <cylinder radius="0.06" length="6.35"/>
      </geometry>
      <material name="Blue"/>
    </visual>

    <visual>
      <origin rpy="1.5708 0 0" xyz="0 0 0.02"/>
      <geometry>
        <cylinder radius="0.1" length="0.04"/>
      </geometry>
      <material name="Red"/>
    </visual>

  </link>

  <!-- Joint 3: Elbow Pitch Joint -->
  <joint name="Elbow_Pitch" type="revolute">
    <parent link="B3"/>
    <child link="B4"/>
    <origin rpy="0 0 0" xyz="6.377 0 -0.1524"/>
    <axis xyz="0 1 0"/>
    <limit lower="-2.75064" upper="0" effort="1074" velocity="0.0560"/>
  </joint>


  <!-- Link 4 -->
  <link name="B4">

    <inertial>
      <origin rpy="0 0 0" xyz="3.53 0 0.0066"/>
      <mass value="87.42"/>
      <inertia ixx="1.59" ixy="0.8021" ixz="-3.786" iyy="632.9" iyz="-0.08" izz="632.51"/>
    </inertial>

    <visual>
      <origin rpy="1.5708 0 1.5708" xyz="3.53 0 0"/>
      <geometry>
        <cylinder radius="0.06" length="7.06"/>
      </geometry>
      <material name="Blue"/>
    </visual>

    <visual>
      <origin rpy="1.5708 0 0" xyz="0 0 0.02"/>
      <geometry>
        <cylinder radius="0.1" length="0.04"/>
      </geometry>
      <material name="Red"/>
    </visual>

  </link>

  <!-- Joint 4: Wrist Pitch Joint -->
  <joint name="Wrist_Pitch" type="revolute">
    <parent link="B4"/>
    <child link="B5"/>
    <origin rpy="0 0 0" xyz="7.06 0 -0.1524"/>
    <axis xyz="0 1 0"/>
    <limit lower="-2.0316" upper="2.0316" effort="470" velocity="0.0831"/>
  </joint>


  <!-- Link 5 -->
  <link name="B5">

    <inertial>
      <origin rpy="0 0 0" xyz="0.2286 0 0"/>
      <mass value="8.48"/>
      <inertia ixx="0.0893" ixy="0" ixz="0" iyy="0.402" iyz="0" izz="0.402"/>
    </inertial>

    <visual>
      <origin rpy="1.5708 0 1.5708" xyz="0.2286 0 0"/>
      <geometry>
        <cylinder radius="0.06" length="0.4572"/>
      </geometry>
      <material name="Blue"/>
    </visual>

    <visual>
      <origin rpy="1.5708 0 0" xyz="0 0 0.02"/>
      <geometry>
        <cylinder radius="0.1" length="0.04"/>
      </geometry>
      <material name="Red"/>
    </visual>

  </link>

  <!-- Joint 5: Wrist Yaw Joint -->
  <joint name="Wrist_Yaw" type="revolute">
    <parent link="B5"/>
    <child link="B6"/>
    <origin rpy="0 0 0" xyz="0.4572 0 0"/>
    <axis xyz="0 0 1"/>
    <limit lower="-2.0316" upper="2.0316" effort="470" velocity="0.0831"/>
  </joint>

  <!-- Link 6 -->
  <link name="B6">

    <inertial>
      <origin rpy="0 0 0" xyz="0.381 0 0"/>
      <mass value="45.94"/>
      <inertia ixx="0.408" ixy="0" ixz="0" iyy="4.68" iyz="0" izz="4.68"/>
    </inertial>

    <visual>
      <origin rpy="1.5708 0 1.5708" xyz="0.381 0 0"/>
      <geometry>
        <cylinder radius="0.06" length="0.762"/>
      </geometry>
      <material name="Blue"/>
    </visual>

    <visual>
      <origin rpy="0 0 0" xyz="0 0 0.02"/>
      <geometry>
        <cylinder radius="0.1" length="0.04"/>
      </geometry>
      <material name="Red"/>
    </visual>

  </link>

  <!-- Joint 6: Wrist Roll Joint -->
  <joint name="Wrist_Roll" type="revolute">
    <parent link="B6"/>
    <child link="B7"/>
    <origin rpy="0 0 0" xyz="0.762 0 0"/>
    <axis xyz="1 0 0"/>
    <limit lower="-7.714" upper="7.714" effort="470" velocity="0.0831"/>
  </joint>

  <!-- Link 7 -->
  <link name="B7">

    <inertial>
      <origin rpy="0 0 0" xyz="0.3302 0 0"/>
      <mass value="45.21"/>
      <inertia ixx="1.903" ixy="0.385" ixz="0.966" iyy="3.816" iyz="0.353" izz="2.823"/>
    </inertial>

    <visual>
      <origin rpy="1.5708 0 1.5708" xyz="0.3302 0 0"/>
      <geometry>
        <cylinder radius="0.06" length="0.6604"/>
      </geometry>
      <material name="Blue"/>
    </visual>

    <visual>
      <origin rpy="0 1.5708 0" xyz="0 0 0.02"/>
      <geometry>
        <cylinder radius="0.1" length="0.04"/>
      </geometry>
      <material name="Red"/>
    </visual>

  </link>

  <!-- Fixed End-effector Joint -->
  <joint name="joint_ee_fixed" type="fixed">
    <parent link="B7"/>
    <child link="link_ee"/>
    <origin rpy="0 0 0" xyz="0.6604 0 0"/>
  </joint>

  <!-- End-Effector -->
  <link name="link_ee">

    <inertial>
      <origin rpy="0 0 0" xyz="0 0 0"/>
      <mass value="0"/>
      <inertia ixx="0" ixy="0" ixz="0" iyy="0" iyz="0" izz="0"/>
    </inertial>

    <visual>
      <origin rpy="0 0 0" xyz="0 0 0"/>
      <geometry>
        <sphere radius="0.06"/>
      </geometry>
      <material name="Red"/>
    </visual>
  </link>


</robot>